<?xml version="1.0"?>
<robot name="rover" xmlns:xacro="http://www.ros.org/wiki/xacro">

  <xacro:property name="chassis_length" value="0.50"/>
  <xacro:property name="chassis_width"  value="0.40"/>
  <xacro:property name="chassis_height" value="0.25"/>
  
  <xacro:property name="wheel_radius"   value="0.10"/>
  <xacro:property name="wheel_thickness" value="0.05"/>
  
  <xacro:property name="wheel_offset_x" value="0.18"/> <xacro:property name="wheel_offset_y" value="0.225"/> <xacro:property name="wheel_offset_z" value="-0.05"/> <material name="dark_grey"><color rgba="0.2 0.2 0.2 1.0"/></material>
  <material name="black"><color rgba="0.0 0.0 0.0 1.0"/></material>
  <material name="blue"><color rgba="0.0 0.0 0.8 1.0"/></material>
  <material name="red"><color rgba="0.8 0.0 0.0 1.0"/></material>

  <link name="base_footprint"/>

  <link name="base_link">
    <visual>
      <origin xyz="0 0 0" rpy="0 0 0"/>
      <geometry>
        <box size="${chassis_length} ${chassis_width} ${chassis_height}"/>
      </geometry>
      <material name="dark_grey"/>
    </visual>
  </link>

  <joint name="base_joint" type="fixed">
    <parent link="base_footprint"/>
    <child link="base_link"/>
    <origin xyz="0 0 ${wheel_radius - wheel_offset_z}" rpy="0 0 0"/>
  </joint>

  <xacro:macro name="wheel" params="prefix x_reflect y_reflect">
    <link name="${prefix}_wheel">
      <visual>
        <origin xyz="0 0 0" rpy="${pi/2} 0 0"/>
        <geometry>
          <cylinder radius="${wheel_radius}" length="${wheel_thickness}"/>
        </geometry>
        <material name="black"/>
      </visual>
    </link>

    <joint name="${prefix}_wheel_joint" type="continuous">
      <parent link="base_link"/>
      <child link="${prefix}_wheel"/>
      <origin xyz="${x_reflect * wheel_offset_x} ${y_reflect * wheel_offset_y} ${wheel_offset_z}" rpy="0 0 0"/>
      <axis xyz="0 1 0"/> </joint>
  </xacro:macro>

  <xacro:wheel prefix="front_left"  x_reflect="1"  y_reflect="1" />
  <xacro:wheel prefix="front_right" x_reflect="1"  y_reflect="-1" />
  <xacro:wheel prefix="rear_left"   x_reflect="-1" y_reflect="1" />
  <xacro:wheel prefix="rear_right"  x_reflect="-1" y_reflect="-1" />

  <link name="bno055">
    <visual>
      <geometry>
        <box size="0.03 0.02 0.01"/>
      </geometry>
      <material name="blue"/>
    </visual>
  </link>

  <joint name="imu_joint" type="fixed">
    <parent link="base_link"/>
    <child link="bno055"/>
    <!-- This configuration is based on my estimate for where the center of the chip is
    the IMU is mounted in a right-handed X right Y forward configuration. -->
    <origin xyz="-0.03928461 -0.050864 0.14345" rpy="0 0 ${pi/2}"/>
  </joint>


  <link name="lidar_frame">
    <visual>
      <geometry>
        <cylinder radius="0.061331" length="0.038040"/>
      </geometry>
      <material name="blue"/>
    </visual>
  </link>

  <joint name="lidar_joint" type="fixed">
    <parent link="base_link"/>
    <child link="laser_frame"/>
    <origin xyz="0.0 0.043684 .19576183" rpy="0 ${22 * pi / 180} 0"/>
  </joint>


  <link name="camera_link">
    <visual>
      <geometry>
        <box size="0.02 0.06 0.02"/>
      </geometry>
      <material name="blue"/>
    </visual>
  </link>

  <joint name="camera_joint" type="fixed">
    <parent link="base_link"/>
    <child link="camera_link"/>
    <origin xyz=".196296 .060 .135925" rpy="0 0 0"/>
  </joint>

  <link name="camera_link_optical"/>
  <joint name="camera_optical_joint" type="fixed">
    <parent link="camera_link"/>
    <child link="camera_link_optical"/>
    <origin xyz="0 0 0" rpy="-${pi/2} 0 -${pi/2}"/>
  </joint>

</robot>
